<?xml version="1.0"?>
<robot xmlns:xacro="http://www.ros.org/wiki/xacro" name="cleanbot">
    
    <!-- 包含真实硬件的ros2_control配置 -->
    <xacro:include filename="$(find cleanbot_control)/config/cleanbot_real.ros2_control.xacro"/>
    
    <!-- 基础结构 -->
    <link name="base_footprint"/>
    
    <link name="base_link">
        <visual>
            <geometry>
                <cylinder radius="0.15" length="0.12"/>
            </geometry>
            <material name="white">
                <color rgba="1 1 1 0.8"/>
            </material>
        </visual>
        <collision>
            <geometry>
                <cylinder radius="0.15" length="0.12"/>
            </geometry>
        </collision>
        <inertial>
            <mass value="1.0"/>
            <inertia ixx="0.01" ixy="0.0" ixz="0.0" iyy="0.01" iyz="0.0" izz="0.01"/>
        </inertial>
    </link>
    
    <joint name="base_to_footprint" type="fixed">
        <parent link="base_footprint"/>
        <child link="base_link"/>
        <origin xyz="0 0 0.06" rpy="0 0 0"/>
    </joint>
    
    <!-- 左轮 -->
    <link name="left_wheel_link">
        <visual>
            <origin xyz="0 0 0" rpy="1.57079 0 0"/>
            <geometry>
                <cylinder radius="0.032" length="0.015"/>
            </geometry>
            <material name="black">
                <color rgba="0 0 0 0.8"/>
            </material>
        </visual>
        <collision>
            <origin xyz="0 0 0" rpy="1.57079 0 0"/>
            <geometry>
                <cylinder radius="0.032" length="0.015"/>
            </geometry>
        </collision>
        <inertial>
            <mass value="0.05"/>
            <inertia ixx="0.0001" ixy="0.0" ixz="0.0" iyy="0.0001" iyz="0.0" izz="0.0001"/>
        </inertial>
    </link>
    
    <joint name="left_wheel_joint" type="continuous">
        <parent link="base_link"/>
        <child link="left_wheel_link"/>
        <origin xyz="0 0.1 -0.05" rpy="0 0 0"/>
        <axis xyz="0 1 0"/>
    </joint>
    
    <!-- 右轮 -->
    <link name="right_wheel_link">
        <visual>
            <origin xyz="0 0 0" rpy="1.57079 0 0"/>
            <geometry>
                <cylinder radius="0.032" length="0.015"/>
            </geometry>
            <material name="black">
                <color rgba="0 0 0 0.8"/>
            </material>
        </visual>
        <collision>
            <origin xyz="0 0 0" rpy="1.57079 0 0"/>
            <geometry>
                <cylinder radius="0.032" length="0.015"/>
            </geometry>
        </collision>
        <inertial>
            <mass value="0.05"/>
            <inertia ixx="0.0001" ixy="0.0" ixz="0.0" iyy="0.0001" iyz="0.0" izz="0.0001"/>
        </inertial>
    </link>
    
    <joint name="right_wheel_joint" type="continuous">
        <parent link="base_link"/>
        <child link="right_wheel_link"/>
        <origin xyz="0 -0.1 -0.05" rpy="0 0 0"/>
        <axis xyz="0 1 0"/>
    </joint>
    
    <!-- IMU -->
    <link name="imu_link"/>
    
    <joint name="imu_joint" type="fixed">
        <parent link="base_link"/>
        <child link="imu_link"/>
        <origin xyz="0 0 0.02" rpy="0 0 0"/>
    </joint>
    
    <!-- 调用ros2_control宏 -->
    <xacro:cleanbot_ros2_control_real/>
    
</robot>

